Workbook

Sheet Account Overview
A1: Customer 360° — Account Summary
A2: Enriched enterprise account profiles — firmographics, products, spend, intent & growth signals
A4: Account ID | B4: Account Name | C4: City / State | D4: Industry | E4: Sub-Industry | F4: FTE Size | G4: Revenue Range | H4: AU Sites | I4: Global Sites | J4: Priority Score | K4: Priority Label | L4: Total TCV | M4: TCV Growth (3Yr) | N4: Share of Wallet | O4: Spend Potential Tier
A5: ACC001 | B5: IronBuild Infrastructure | C5: Newcastle, NSW | D5: Construction | E5: Infrastructure & Civil Projects | F5: 500–1000 | G5: $100M–$250M | H5: 8 | I5: 8 | J5: 0.82 | K5: High | L5: $450K | M5: 350% | N5: 2.0% | O5: Very High
A6: ACC002 | B6: BlueHarbor Logistics | C6: Fremantle, WA | D6: Transport & Logistics | E6: Cold Chain & Regional Freight | F6: 150–300 | G6: $50M–$100M | H6: 5 | I6: 5 | J6: 0.55 | K6: Medium | L6: $150K | M6: 0% | N6: 4.7% | O6: Medium
A7: ACC003 | B7: SouthernGrid Energy | C7: Adelaide, SA | D7: Energy | E7: Utilities & Grid Infrastructure | F7: 1000+ | G7: $250M–$500M | H7: 15 | I7: 19 | J7: 0.64 | K7: Medium | L7: $1.6M | M7: 33% | N7: 3.3% | O7: Very High
A8: ACC004 | B8: ApexHealth Clinics | C8: Melbourne, VIC | D8: Healthcare | E8: Aged Care & Clinical Services | F8: 300–500 | G8: $50M–$100M | H8: 9 | I8: 9 | J8: 0.67 | K8: Medium | L8: $600K | M8: 50% | N8: 3.3% | O8: High
A9: ACC005 | B9: HorizonAgri Advisory | C9: Toowoomba, QLD | D9: Agriculture | E9: Agri Consulting & Services | F9: 50–150 | G9: $10M–$25M | H9: 2 | I9: 2 | J9: 0.32 | K9: Low | L9: $50K | M9: 0% | N9: 11.1% | O9: Low
A10: ACC006 | B10: NovaTech Industrial | C10: Geelong, VIC | D10: Manufacturing | E10: Industrial Automation & Equipment | F10: 1000+ | G10: $500M–$1B | H10: 12 | I10: 17 | J10: 0.71 | K10: High | L10: $2.25M | M10: 25% | N10: 2.4% | O10: Very High
A11: ACC007 | B11: CoastalBuild Projects | C11: Gold Coast, QLD | D11: Construction | E11: Commercial & Mixed-use Development | F11: 150–300 | G11: $50M–$100M | H11: 4 | I11: 4 | J11: 0.58 | K11: Medium | L11: $300K | M11: 50% | N11: 4.0% | O11: Medium
A12: ACC008 | B12: MetroServe Financial | C12: Sydney, NSW | D12: Financial Services | E12: Business Advisory & Taxation | F12: 50–150 | G12: $25M–$50M | H12: 3 | I12: 4 | J12: 0.56 | K12: Medium | L12: $200K | M12: 33% | N12: 3.3% | O12: Medium
A13: ACC009 | B13: TerraLink Mining | C13: Perth, WA | D13: Mining | E13: Mining Operations & Field Services | F13: 500–1000 | G13: $100M–$250M | H13: 10 | I13: 12 | J13: 0.75 | K13: High | L13: $800K | M13: 60% | N13: 3.1% | O13: High
A14: ACC010 | B14: EduCore Learning | C14: Parramatta, NSW | D14: Education | E14: Vocational & Professional Training | F14: <50 | G14: $5M–$10M | H14: 1 | I14: 1 | J14: 0.28 | K14: Low | L14: $100K | M14: 0% | N14: 28.6% | O14: Very Low

Sheet Products & Intent
A1: Active Products, Intent Signals & Technographics
A2: Current product portfolio, top intent domains with scores, tech maturity and competitor landscape
A4: Account ID | B4: Account Name | C4: Active Products | D4: Intent Domain 1 | E4: Score 1 | F4: Intent Domain 2 | G4: Score 2 | H4: Intent Domain 3 | I4: Score 3 | J4: Tech Maturity | K4: Competitors
A5: ACC001 | B5: IronBuild Infrastructure | C5: Business Internet, SDWAN, Mobility | D5: Networking | E5: 85 | F5: IoT & Edge | G5: 72 | H5: Security | I5: 68 | J5: High | K5: Cisco, Optus
A6: ACC002 | B6: BlueHarbor Logistics | C6: Business Internet, Mobility | D6: Fleet Mgmt & Compliance | E6: 55 | F6: — | G6: — | H6: — | I6: — | J6: Medium | K6: —
A7: ACC003 | B7: SouthernGrid Energy | C7: Business Internet, Enterprise Ethernet, SDWAN, Mobility, Security | D7: Digital Infrastructure | E7: 90 | F7: Security | G7: 86 | H7: Business Continuity | I7: 80 | J7: Very High | K7: Optus, NBN Enterprise
A8: ACC004 | B8: ApexHealth Clinics | C8: Business Internet, SDWAN, UCaaS, Mobility | D8: Collaboration & UC | E8: 75 | F8: Networking | G8: 68 | H8: Security | I8: 62 | J8: High | K8: Optus
A9: ACC005 | B9: HorizonAgri Advisory | C9: Business Internet | D9: — | E9: — | F9: — | G9: — | H9: — | I9: — | J9: Low | K9: —
A10: ACC006 | B10: NovaTech Industrial | C10: Business Internet, Enterprise Ethernet, SDWAN, Mobility, Cloud, Security | D10: Digital Infrastructure | E10: 94 | F10: Cloud & Data | G10: 90 | H10: Security | I10: 88 | J10: Very High | K10: Optus, NBN Enterprise
A11: ACC007 | B11: CoastalBuild Projects | C11: Business Internet, SDWAN, Mobility | D11: Networking | E11: 60 | F11: — | G11: — | H11: — | I11: — | J11: Medium | K11: Optus
A12: ACC008 | B12: MetroServe Financial | C12: Business Internet, UCaaS, Mobility | D12: Collaboration & Mobility | E12: 45 | F12: — | G12: — | H12: — | I12: — | J12: Medium | K12: —
A13: ACC009 | B13: TerraLink Mining | C13: Business Internet, SDWAN, Mobility, IoT | D13: IoT & Edge | E13: 82 | F13: Networking | G13: 74 | H13: Mobility & Workforce | I13: 70 | J13: High | K13: Optus IoT
A14: ACC010 | B14: EduCore Learning | C14: Business Internet, Mobility | D14: — | E14: — | F14: — | G14: — | H14: — | I14: — | J14: Very Low | K14: —
D16: Intent_Domain_1 | E16: Score_1 | F16: Domain_1_Top_Keywords (Top 5) | G16: Intent_Domain_2 | H16: Score_2 | I16: Domain_2_Top_Keywords (Top 5) | J16: Intent_Domain_3 | K16: Score_3 | L16: Domain_3_Top_Keywords (Top 5)
D17: Networking | E17: 85 | F17: SD-WAN optimisation, Ethernet networking, bandwidth expansion, network modernisation, site connectivity | G17: IoT & Edge | H17: 72 | I17: IoT networks, asset monitoring, edge connectivity, device management, remote telemetry | J17: Security | K17: 68 | L17: network security, secure SD-WAN, threat protection, firewall upgrades, perimeter security
D19: Digital Infrastructure | E19: 90 | F19: Telecommunications infrastructure, network resilience, high-availability networks, carrier diversity, core networking | G19: Security | H19: 86 | I19: Secure connectivity, cyber analytics, threat monitoring, network security, compliance | J19: Business Continuity | K19: 80 | L19: Disaster recovery, network redundancy, failover architecture, continuity planning, resilience testing
D20: Collaboration & UC | E20: 75 | F20: UCaaS platforms, VoIP, cloud video conferencing, collaboration tools, call quality | G20: Networking | H20: 68 | I20: Network performance, SD-WAN optimisation, bandwidth management, site connectivity, latency reduction | J20: Security | K20: 62 | L20: Secure access, identity management, compliance, data protection, zero trust
D22: Digital Infrastructure | E22: 94 | F22: Cloud connectivity, data centre interconnect, high-performance networking, carrier-neutral access, global networks | G22: Cloud & Data | H22: 90 | I22: Multi-cloud networking, workload connectivity, latency optimisation, data transfer efficiency, cloud optimisation | J22: Security | K22: 88 | L22: Cloud security, zero trust, secure access, data protection, threat monitoring
D23: Networking | E23: 60 | F23: Temporary connectivity, rapid deployment networks, wireless backhaul, site setup, short-term bandwidth
D25: IoT & Edge | E25: 82 | F25: Fleet monitoring, connected vehicles, IoT platforms, edge devices, telemetry data | G25: Networking | H25: 74 | I25: Wireless connectivity, resilient networks, bandwidth scaling, remote sites, SD-WAN optimisation | J25: Mobility & Workforce | K25: 70 | L25: Mobile networks, field connectivity, SIM management, coverage optimisation

Sheet Complete
A1: Account ID | B1: Account Name | C1: City / State | D1: Industry | E1: Sub-Industry | F1: FTE Size | G1: Revenue Range | H1: Local Sites | I1: Global Sites | J1: Spend Potential Tier | K1: Intent Domain 1 | L1: Score 1 | M1: Keyword 1 | N1: Intent Domain 2 | O1: Score 2 | P1: Keyword 2 | Q1: Intent Domain 3 | R1: Score 3 | S1: Keyword 3 | T1: Intent_Badge | U1: Tech Maturity | V1: Competitors | W1: YoY Growth | X1: Expansion | Y1: Acquisition | Z1: Partnership | AA1: Hiring | AB1: Funding | AC1: Layoff | AD1: Financial Risk
A2: ACC001 | B2: AvePoint | C2: Jersey City, NJ | D2: Information Technology | E2: Data Security Software Products | F2: 500+ | G2: $100M - $500M | H2: 4 | I2: 10+ | J2: Very High | K2: Security Network | L2: 85 | M2: zero trust architecture, SIEM platforms, endpoint detection, cloud security posture, threat analytics | N2: Cloud Services | O2: 80 | P2: multi-cloud optimisation, cloud scalability, CDN performance, workload distribution, data transfer efficiency | Q2: Digital Infrastructure | R2: 78 | S2: SD-WAN optimisation, global backbone connectivity, carrier benchmarking, network resilience, secure edge | T2: Explicit | U2: Advanced | V2: — | W2: — | X2: ✓ Yes | Y2: ✓ Yes | Z2: ✓ Yes | AA2: — | AB2: ✓ Yes | AC2: — | AD2: —
A3: ACC002 | B3: Moderna | C3: Cambridge, MA | D3: Professional, Scientific, and Technical Services | E3: Biotechnology | F3: 500+ | G3: $500M+ | H3: 1 | I3: 1 | J3: High | K3: — | L3: — | M3: — | N3: — | O3: — | P3: — | Q3: — | R3: — | S3: — | T3: No intent | U3: Developing | V3: — | W3: — | X3: ✓ Yes | Y3: — | Z3: — | AA3: — | AB3: ✓ Yes | AC3: Yes | AD3: —
A4: ACC003 | B4: Suncoast Credit Union | C4: Tampa, FL | D4: Finance and Insurance | E4: Banking | F4: 500+ | G4: $500M+ | H4: 1 | I4: 1 | J4: High | K4: Cloud Services | L4: 90 | M4: Cloud migration, hybrid cloud, workload optimisation | N4: Security Network | O4: 84 | P4: secure access, compliance, network security | Q4: — | R4: — | S4: — | T4: Explicit | U4: Advanced | V4: — | W4: — | X4: ✓ Yes | Y4: — | Z4: ✓ Yes | AA4: — | AC4: — | AD4: —
A5: ACC004 | B5: SolomonEdwards | C5: Wayne, PA | D5: Professional, Scientific, and Technical Services | E5: Business Services | F5: 500+ | G5: $500M+ | H5: 5 | I5: 5 | J5: High | K5: Cloud Services | L5: 35 | M5: Multi-cloud networking, digital infrastructure | N5: Security Network | O5: 30 | P5: network security, secure connectivity | Q5: — | R5: — | S5: — | T5: Low | U5: Advanced | V5: — | W5: — | X5: ✓ Yes | Y5: ✓ Yes | Z5: ✓ Yes | AA5: — | AC5: — | AD5: —
A6: ACC005 | B6: BAYSTAR | C6: Pasadena, TX | D6: Manufacturing | E6: Chemical Manufacturing | F6: 150 - 300 | G6: $10M - $100M | H6: 2 | I6: 2 | J6: Very High | K6: Wireless Connectivity | L6: 92 | M6: Private LTE, wireless scaling, industrial connectivity | N6: — | O6: — | P6: — | Q6: — | R6: — | S6: — | T6: Explicit | U6: Advanced | V6: — | W6: — | X6: ✓ Yes | Y6: — | Z6: ✓ Yes | AA6: ✓ Yes | AC6: — | AD6: —
A7: ACC006 | B7: CookUnity | C7: Brooklyn, NY | D7: Manufacturing | E7: Food and Beverage Manufacturing | F7: 500+ | G7: $100M - $500M | H7: 7 | I7: 8 | J7: Medium | K7: IoT Platform | L7: 35 | M7: Connected devices, telemetry platforms | N7: Cloud Services | O7: 30 | P7: cloud services, basic workloads | Q7: — | R7: — | S7: — | T7: Low | U7: Advanced | V7: Comcast | W7: — | X7: ✓ Yes | Y7: ✓ Yes | Z7: ✓ Yes | AA7: — | AB7: ✓ Yes | AC7: — | AD7: Yes
A8: ACC007 | B8: BCI Brands | C8: New York, NY | D8: Retail | E8: Apparel and Fashion - Retail Trade | F8: 150 - 300 | G8: $10M - $100M | H8: 1 | I8: 1 | J8: Medium | K8: Cloud Services | L8: 88 | M8: Cloud optimisation, multi-cloud networking | N8: Fiber Connectivity | O8: 78 | P8: fiber expansion, broadband upgrades | Q8: Wireless Connectivity | R8: 75 | S8: wireless coverage, site connectivity | T8: Explicit | U8: Advanced | V8: — | W8: — | X8: — | Y8: ✓ Yes | Z8: ✓ Yes | AA8: — | AC8: — | AD8: —
A9: ACC008 | B9: Bisig Impact Group | C9: Louisville, KY | D9: Professional, Scientific, and Technical Services | E9: Advertising Services | F9: Less than 50 | G9: $5M - $10M | H9: 1 | I9: 1 | J9: Low | K9: Cloud Services | L9: 33 | M9: Basic cloud adoption, collaboration tools | N9: Security Network | O9: 25 | P9: minimal security interest | Q9: — | R9: — | S9: — | T9: Low | U9: Advanced | V9: — | W9: — | X9: — | Y9: — | Z9: — | AA9: — | AC9: — | AD9: —
A10: ACC009 | B10: Flynn Construction Inc. | C10: Austin, TX | D10: Construction | E10: Construction | F10: 50 - 150 | G10: $5M - $10M | H10: 1 | I10: 1 | J10: Low | K10: Cloud Services | L10: 30 | M10: Light cloud collaboration interest | N10: — | O10: — | P10: — | Q10: — | R10: — | S10: — | T10: Low | U10: Advanced | V10: — | W10: — | X10: — | Y10: — | Z10: — | AA10: — | AC10: — | AD10: —
A11: ACC010 | B11: Vuteq USA, Inc. | C11: Georgetown, KY | D11: Manufacturing | E11: Automobile / Vehicle / Original Equipment Manufacturing | F11: 300 - 500 | G11: $500M+ | H11: 3 | I11: 3 | J11: Low | K11: Cloud Services | L11: 40 | M11: Cloud optimisation, enterprise connectivity | N11: Wireless Connectivity | O11: 32 | P11: marginal wireless signals | Q11: — | R11: — | S11: — | T11: Low | U11: Advanced | V11: — | W11: — | X11: — | Y11: — | Z11: — | AA11: — | AC11: — | AD11: —

Sheet Customer360
A1: unique_id | C1: company_name | D1: final_website | E1: compguid | F1: compname | G1: compnameaka | H1: compaddr | I1: compcity | J1: compstate | K1: compcountry | L1: location_type | M1: compzipcode | N1: compglobalregions | O1: compwebsite | P1: comp_phone_number | Q1: compparentcompany | R1: compparentcompanyguid | S1: compworldwideparentcompany | T1: compworldwideparentguid | U1: compfoundingyear | V1: compempcount | W1: employee_range_redefined_buckets | X1: revenue_range_redefined_buckets | Y1: compsubindustry | Z1: naics_industry | AA1: compsiccodes | AB1: compsicdescription | AC1: compnaicscodes | AD1: compnaicsdescription | AE1: compissubsidiary | AF1: complegalstatus | AG1: type_of_company | AH1: description | AI1: products | AJ1: services | AK1: subsidiaries_brands | AL1: hq | AM1: other_locations | AN1: email | AO1: contact_page_url | AP1: social_media_links | AQ1: years_in_business | AR1: years_in_business_buckets | AS1: total_sites_local | AT1: total_sites_global | AU1: tech_id_list | AV1: tech_series_list | AW1: tech_categories_list | AX1: tech_sub_categories_list | AY1: tech_name_list | AZ1: tech_vendor_list | BA1: high_maturity_tech_count | BB1: medium_maturity_tech_count | BC1: low_maturity_tech_count | BD1: num_unique_tech_tools | BE1: num_unique_tech_categories | BF1: tech_stack_breadth_score | BG1: recent_tech_adoption_flag_vendor | BH1: recent_tech_adoption_count_vendor | BI1: has_foundational_tech_category | BJ1: has_intermediate_tech_category | BK1: has_advanced_tech_category | BL1: composite_tech_maturity_level | BM1: tech_relevancy_level | BN1: maturity_purity_score | BO1: tech_maturity_index | BP1: is_cloud_flag | BQ1: is_cloud_count | BR1: is_iaas_paas_flag | BS1: is_iaas_paas_count | BT1: is_saas_flag | BU1: is_saas_count | BV1: is_ai_ml_flag | BW1: is_ai_ml_count | BX1: is_analytics_flag | BY1: is_analytics_count | BZ1: is_security_flag | CA1: is_security_count | CB1: is_robotics_flag | CC1: is_robotics_count | CD1: is_iot_flag | CE1: is_iot_count | CF1: is_wireless_flag | CG1: is_wireless_count | CH1: is_wireline_flag | CI1: is_wireline_count | CJ1: is_fixed_and_mobile_connectivity_flag | CK1: is_fixed_and_mobile_connectivity_count | CL1: is_uc_and_hosted_voice_flag | CM1: is_uc_and_hosted_voice_count | CN1: is_m365_collaboration_flag | CO1: is_m365_collaboration_count | CP1: is_enterprise_mobility_flag | CQ1: is_enterprise_mobility_count | CR1: is_marketing_flag | CS1: is_marketing_count | CT1: is_colocation_and_hosting_flag | CU1: is_colocation_and_hosting_count | CV1: is_other_flag | CW1: is_other_count | CX1: is_att_tech | CY1: is_verizon_tech | CZ1: is_tmobile_tech | DA1: is_comcast_tech | DB1: is_spectrum_tech | DC1: is_lumen_tech | DD1: company_annual_ict_spending | DE1: company_annual_ict_spending_bucket | DF1: company_annual_hw_spending | DG1: company_annual_hw_spending_bucket | DH1: company_annual_sw_spending | DI1: company_annual_sw_spending_bucket | DJ1: company_annual_it_comnet_spending | DK1: company_annual_it_comnet_spending_bucket | DL1: company_annual_it_services_spending | DM1: company_annual_it_services_spending_bucket | DN1: company_annual_it_staff_spending | DO1: company_annual_it_staff_spending_bucket | DP1: company_annual_telco_spending | DQ1: company_annual_telco_spending_bucket | DR1: spend_priority_label_llm | DS1: total_intent_velocity | DT1: competitive_keyword_count | DU1: price_sensitive_keyword_count | DV1: change_initiative_keyword_count | DW1: evaluation_keyword_count | DX1: implementation_keyword_count | DY1: support_signal_count | DZ1: total_keywords | EA1: fiber_connectivity_intent_share | EB1: wireless_connectivity_intent_share | EC1: internet_broadband_intent_share | ED1: network_edge_intent_share | EE1: security_network_intent_share | EF1: security_identity_intent_share | EG1: collaboration_voice_intent_share | EH1: contact_center_intent_share | EI1: cloud_services_intent_share | EJ1: iot_platform_intent_share | EK1: managed_services_intent_share | EL1: digital_transformation_intent_share | EM1: product_diversity | EN1: primary_category | EO1: max_category_intent | EP1: multi_category_flag | EQ1: competitive_threat_flag | ER1: evaluation_stage_flag | ES1: ready_to_buy_flag | ET1: intent_quality_tier | EU1: avg_keywords_per_category | EV1: annual_revenue_2023 | EW1: annual_revenue_2024 | EX1: annual_revenue_2025 | EY1: quarterly_revenue_q1_2025 | EZ1: quarterly_revenue_q2_2025 | FA1: quarterly_revenue_q3_2025 | FB1: quarterly_revenue_q4_2025 | FC1: net_income_2023 | FD1: net_income_2024 | FE1: net_income_2025 | FF1: gross_profit_2023 | FG1: gross_profit_2024 | FH1: gross_profit_2025 | FI1: net_profit_margin_2023 | FJ1: net_profit_margin_2024 | FK1: net_profit_margin_2025 | FL1: revenue_growth_pct | FM1: revenue_growth_pct_buckets | FN1: business_expansion_flag | FO1: recency_business_expansion | FP1: acquisition_merger_flag | FQ1: number_of_acquisition_merger | FR1: recency_acquisition_merger | FS1: partnership_alliance_flag | FT1: recency_partnership_alliance | FU1: hiring_flag | FV1: recency_hiring | FW1: layoff_flag | FX1: recency_layoff | FY1: tech_adoption_count | FZ1: growth_tier | GA1: debt_year | GB1: debt_amount | GC1: funding_flag | GD1: funding_amount | GE1: recency_funding | GF1: investment_year | GG1: investment_amount | GH1: amazon_store | GI1: multiple_currencies_supported | GJ1: seo_keywords | GK1: accept_digital_payments | GL1: ad_tech_other | GM1: ad_tech_adroll | GN1: advertising_pixel | GO1: mobile_app | GP1: social_media_badges | GQ1: ecommerce_platforms | GR1: total_social_media_platforms | GS1: total_ecommerce_platforms | GT1: online_business | GU1: lead_priority_score | GV1: lead_priority_label | GW1: created_at | GX1: modified_at | GY1: growth_tier_reasoning | GZ1: total_sites_local_buckets | HA1: total_sites_global_buckets | HB1: key_priorities_column
A2: fe3ff36b-ea93-54be-b45c-ba325a87086a | B2: =VLOOKUP(C2,Complete!#REF!,1,0) -> #REF! | C2: Accelirate Inc. | D2: https://www.accelirate.com/ | E2: BE097148B6904C1E | F2: Accelirate Inc. | G2: Accelirate | Inc. | Accelirate Inc. | H2: 440 Sawgrass Corporate Pkwy | I2: Fort Lauderdale | J2: Florida | K2: United States | L2: Urban | M2: 33325 | N2: North America | O2: accelirate.com | P2: +1 877 657 6006 | Q2: Accelirate, Inc. | R2: BE097148B6904C1E | S2: Accelirate, Inc. | T2: BE097148B6904C1E | U2: 2016 | V2: 503 | W2: 500+ | X2: $100M - $500M | Y2: IT Services | Z2: Information Technology | AA2: 73 | 7379 | 737902 | 73790200 | AB2: 73 - Business Services | 7379 - Computer Related Services, Nec | 737902 - Computer Related Consulting Services | 73790200 - Computer Related Consulting Services | AC2: 5415 | 54151 | AD2: 5415 - Computer Systems Design and Related Services | 54151 - Computer Systems Design and Related Services | AE2: No | AF2: Privately Held | AG2: AI-powered business automation partner | AH2: Accelirate is a leader in delivering enterprise automation and AI-driven solutions. They aim to build a unified intelligent ecosystem for people, agents, and robots. | AI2: ['AgentBuilder', 'Agentforce', 'AcceliOps Managed Services', 'RPA365®'] | AJ2: ['Agentic Process Automation', 'Agentic Software Testing', 'Agentforce Services', 'RPA Automation', 'GenAI Consulting', 'Intelligent Automation', 'Intelligent Document Processing', 'Integration/Workflow Platform-as-a-Service', 'System of Record Integration', 'Process Re-Engineering', 'RPA Managed Service', 'Robotic Operations Center (ROC)', 'Platform & Cloud Migrations', 'Developer Enablement Training', 'Citizen Developer Enablement Programs', 'Accelirated Process Discovery', 'Accelirated Process Mining', 'COE Implementation', 'Salesforce Consulting', 'Tableau Consulting', 'Mulesoft Integration Services', 'Data Analytics'] | AL2: 440 Sawgrass Corporate Parkway, SSte 210, Sunrise FL 33325 | AM2: ['505 Thornall St, Suite 300, Edison NJ 08837', 'Accelirate Can Limited 1270 Central Parkway West, Unit 102, Mississauga, Ontario, L5C4P4, Canada', 'Sai Radhe Business Center, Redbricks 7th floor, Raja Bahadur Mills Road, Sangamvadi, Pune, Maharashtra 411001', '#116-50 Bogota, Colombia 110111', '#5 SUR-145 Medellin, Colombia 050021,Ste', 'DMC5, Dubai Media City'] | AO2: https://www.accelirate.com/contact/ | AP2: https://www.linkedin.com/company/accelirate-inc | AQ2: 10 | AR2: 5 - 15 | AS2: 2 | AT2: 6 | AU2: 10045.0|10081.0|10095.0|10345.0|10454.0|10610.0|10641.0|10666.0|11539.0|12402.0|12509.0|12535.0|12773.0|14126.0|15731.0|16255.0|16293.0|16303.0|16427.0|16509.0|16621.0|16622.0|16709.0|16849.0|17077.0|17079.0|17082.0|17219.0|17239.0|17342.0|17418.0|17465.0|17693.0|18361.0|1900.0|1908.0|20945.0|21173.0|2208.0|22711.0|22907.0|26573.0|27169.0|27177.0|28134.0|28787.0|29719.0|31846.0|32001.0|32487.0|3325.0|33891.0|35245.0|35280.0|35413.0|35553.0|35637.0|35717.0|35849.0|36044.0|36534.0|36978.0|37547.0|38887.0|40206.0|4076.0|40967.0|410.0|413.0|41453.0|41477.0|41573.0|41583.0|41624.0|4198.0|43417.0|4578.0|4644.0|5309.0|5488.0|5489.0|5639.0|6059.0|6194.0|6296.0|6468.0|6929.0|7140.0|7515.0|7523.0|7681.0|779.0|7793.0|8515.0|852.0|8780.0|8834.0|9532.0|9816.0|9918.0 | AV2: Advertising|Collaborate Design & Publish|Customer Service|Data Management Business Intelligence & Analytics|Emerging Technology|Enterprise Business Solution|Financial Management & GRC|Hardware|Human Capital Management|IT Development/Infrastructure|Marketing|Operations|Retail & Digital Commerce|Sales|Security Devices|Servers|Verticals|Web Tools & Plugins | AW2: Academic & Education Management|Accounting/Finance/Treasury|Advertising Networks|Applicant Tracking Systems|Application Development Tools|Artificial Intelligence & Machine Learning|Business Intelligence|Business Process Management|CRM|Collaborative/Integrated Software|Construction|Data Integration|Data Science|Database Management|Design & Publishing Software|Domain Name Services|E-Commerce Platform/Software|Email Software|Endpoint Security|Enterprise Resource Planning|Frameworks & Libraries|Groupware Software|Human Resources Management|IT Infrastructure & Ops Management|IT Service Management ITSM|Marketing Automation|Operating System|Other Collaboration Software|Other Marketing Software|Other Security Software|Other Vertical Industries Software|Other Web Tools & Plugins|Personal Computer|Programming Languages|Project Management Software|Sales Enablement|Search Marketing|Social Media Systems|Software Configuration Management|Software as a Service|Suites|Web Analytics|Web Content Management Systems|Web Hosting | AX2: AI Platforms|API Management Platforms|Agile Project Management|Authentication Tools|Build Automation Tools|CRM Platforms|Campaign Management Platforms|Cloud Hosting|Cloud Platforms|Collaboration Platforms|Data Preparation|Data Visualization|Database Languages|Developer SDKs|Document Processing|Domain Registrars|ETL Tools|Email Advertising|Email Hosting|Email and Messaging Clients|Energy ERP|Enterprise Analytics Platforms|Enterprise Application Tools|Estimating and Bidding Software|Event Tracking Tools|Financial Planning and Analysis|Form Builders|Frontend Frameworks|General ERP|General-Purpose Languages|Generative AI|Global Payroll|Graphic Design Software|Graphic Design Tools|Healthcare CRM|Identity Verification|Lead Enrichment and Data Intelligence|Learning Experience Platforms (LXP)|Linux Distributions|Machine Learning Frameworks|Machine Learning Libraries|Market Research|Marketplace Platforms|Mobile Operating Systems|Natural Language Processing (NLP)|NoSQL Databases|Open Source CMS|Operating Systems|Password Management|Portfolio Management|Presentation Tools|Process Modeling Tools|Productivity Suites|Programming Language Suites|Recruitment Sourcing Tools|Robotic Process Automation|Robotics and Automation|SEO Tools|Sales Enablement CRM|Scripting Languages|Search Advertising|Search and Indexing Software|Service Desk Software|Session Replay Tools|Shared Hosting|Small Business CRM|Social Media Advertising|Social Media Marketing Tools|Social Proof Tools|Tag Management Systems|Testing Tools|UNIX Variants|Unclassified|Version Control Systems|Video Hosting Platforms|Web Development | AY2: AWS Amazon Web Services|Adobe Photoshop|Alteryx|Amazon|Android|Apache Maven|Automation Anywhere|Batch|Blue Prism|C|CSS|Canonical Ubuntu|Canva|Clearbit|Cognism|Connectifier|Core|Dell Technologies|Elasticsearch|Git|GoDaddy DNS|Google Ads|Google Analytics|Google Global Site Tag|Google Tag Manager|Google Universal Analytics|Hotjar|HubSpot|HubSpot Form Builder|Hugging Face|Informa|Informatica|Java|JavaScript|Jira|Kibana|LastPass|LinkedIn Ads|LinkedIn Insight Tag|LinkedIn Login|LinkedIn Recruiter|LinkedIn Sales Navigator|Linkedin JavaScript SDK|Linode|Linode Hosting|Linux|LiveIntent|Lynda Business|ManageEngine ServiceDesk Plus|Marketo|Microsoft|Microsoft Azure Form Recognizer|Microsoft Azure Machine Learning|Microsoft Exchange Online|Microsoft Office 365|Microsoft Outlook|Microsoft PowerPoint|Microsoft SharePoint|Microsoft SharePoint Online|Microsoft Windows PowerShell|Microsoft common|Mode|MuleSoft Anypoint Platform|NTENT Hosting|Newsle|NoSQL|OpenAI|Oracle|P2 Energy Solutions|PHP|Power BI|Prove formerly Payfone|PyTorch|Python|Quali|R Project|RB2B|Remote|SAP|SQL|Salesforce Health Cloud|Scala|ServiceNow Project Portfolio Management|Sigma|Software AG ARIS Architect & Designer|Tableau|Talend|TensorFlow|Twitter Cards|UiPath|Unix|UseProof|WordPress.org|Yoast|Yoast SEO|YouTube|Zoho common|iOS|jQuery|scikit-learn | AZ2: AWS|Adobe Systems Inc.|Alteryx|Amazon|Apache Software Foundation|Apple|Atlassian|Automation Anywhere|BQE Software Inc|Batch|Blue Prism|COMPILER|Canonical|Canva|Clearbit|Cognism|Connectifier|Dell|EPFL|Elasticsearch|Facebook|GoDaddy|Google|Hotjar Ltd.|HubSpot|Hugging Face Inc|Informa Group PLC|Informatica|International Organization for Standardization|LinkedIn|Linode|LiveIntent Inc.|LogMeIn|Marketo|Microsoft|Mode Analytics|Mulesoft|NTENT|Netscape|NoSQL|Open Source|OpenAI|Oracle|P2 Energy Solutions|Proof Technologies|Prove|Python|QualiSystems Ltd|RB2B|Remote Technology Inc|SAP|Salesforce.com|ServiceNow|Sigma Software|Software AG|Software Freedom Conservancy Inc.|Tableau Software|Talend|The Open Group|The jQuery Foundation Inc|Twitter Inc.|UiPath - Robotic Process Automation|WordPress|World Wide Web Consortium|Yoast B.V|Zoho | BA2: 9 | BB2: 41 | BC2: 45 | BD2: 100 | BE2: 44 | BF2: 0.2875817 | BG2: 1 | BH2: 8 | BI2: 1 | BJ2: 1 | BK2: 1 | BL2: Advanced | BM2: High | BN2: 0.35789474 | BO2: 0.839 | BP2: 1 | BQ2: 3 | BR2: 0 | BS2: 0 | BT2: 1 | BU2: 5 | BV2: 1 | BW2: 9 | BX2: 1 | BY2: 20 | BZ2: 1 | CA2: 3 | CB2: 1 | CC2: 3 | CD2: 0 | CE2: 0 | CF2: 0 | CG2: 0 | CH2: 0 | CI2: 0 | CJ2: 0 | CK2: 0 | CL2: 0 | CM2: 0 | CN2: 0 | CO2: 0 | CP2: 0 | CQ2: 0 | CR2: 1 | CS2: 14 | CT2: 0 | CU2: 0 | CV2: 1 | CW2: 37 | CX2: 0 | CY2: 0 | CZ2: 0 | DA2: 0 | DB2: 0 | DC2: 0 | DD2: 1283112 | DE2: 600K – 2.6M | DF2: 64170 | DG2: 0 – 100K | DH2: 137548 | DI2: 100K – 500K | DJ2: 41645 | DK2: 0 – 100K | DL2: 178796 | DM2: 0 – 200K | DN2: 645306 | DO2: 400K – 2.4M | DP2: 215646 | DQ2: 100K – 500K | DR2: High | DS2: 2392.7 | DT2: 0 | DU2: 65 | DV2: 0 | DW2: 16 | DX2: 0 | DY2: 0 | DZ2: 25 | EA2: 0 | EB2: 0 | EC2: 0 | ED2: 0 | EE2: 0.0088393865 | EF2: 0 | EG2: 0 | EH2: 0 | EI2: 0.017114557 | EJ2: 0 | EK2: 0 | EL2: 0 | EM2: 0 | EN2: CLOUD_SERVICES | EO2: 0.017114557 | EP2: 0 | EQ2: 0 | ER2: 1 | ES2: 0 | EU2: 0 | FN2: 1 | FO2: 1Y | FP2: 0 | FS2: 1 | FT2: 1Y | FU2: 0 | FW2: 0 | FZ2: Medium | GC2: 0 | GU2: 0.74 | GV2: Medium | GW2: 46042.637 | GX2: 46069.558 | GY2: The company shows recent partnership and business expansion activity, but the lack of financial data and hiring signals limits a stronger growth assessment. | GZ2: 1-2 | HA2: 6-10 | HB2: "{\"lead_label\": \"Medium\", \"lead_score\": 0.74, \"tech_reasoning\": \"Tech relevancy unknown.\", \"competitive_reasoning\": \"No competitor or primary vendor usage detected\", \"key_signals\": \"Firmographics: revenue range redefined buckets: $100M - $500M; employee range redefined buckets: 500+; naics industry: Information Technology; location type: Urban; years in business buckets: 5 - 15; total sites local buckets: 1-2; total sites global buckets: 6-10 | Spend: spend priority label llm: High | Growth Signals: growth tier: Medium; business expansion flag: 1.0; partnership alliance flag: 1.0\"}"
A3: d91f1f57-41e3-58d8-b46b-99a5ebb084b8 | B3: =VLOOKUP(C3,Complete!#REF!,1,0) -> #REF! | C3: Advanced Integration Technology | D3: https://www.aint.com/ | E3: 42FDF5D550CBFE7E | F3: Advanced Integration Technology | G3: Aint | Advanced Integration Technology | Advanced Integration Technology | Inc. | H3: 2805 E Plano Pkwy; Suite 300 | I3: Plano | J3: Texas | K3: United States | L3: Sub-Urban | M3: 75074 | N3: North America | O3: aint.com | P3: +1 972 423 8354 | Q3: Advanced Integration Technology, LP | R3: 42FDF5D550CBFE7E | S3: Advanced Integration Technology, LP | T3: 42FDF5D550CBFE7E | U3: 2007 | V3: 255 | W3: 150 - 300 | X3: $10M - $100M | Y3: Aerospace and Aircraft Manufacturing | Z3: Manufacturing | AA3: 3721 | 372199 | 38120101 | AB3: 3721 - Aircraft | 372199 - Aircraft, Nec | 38120101 - Acceleration Indicators And Systems Components, Aerospace | AC3: 336 | 3364 | 33641 | 33 | AD3: 336 - Transportation Equipment Manufacturing | 3364 - Aerospace Product and Parts Manufacturing | 33641 - Aerospace Product and Parts Manufacturing | 33 - Manufacturing | AE3: No | AF3: Privately Held | AG3: Automation, integration, tooling solutions provider | AH3: AIT designs, manufactures and installs automated tooling and equipment for the assembly of aerospace structures, as well as friction stir weld equipment for diversified industrial markets. | AI3: ['AGVs', 'Automated Systems for Part-to-Part Assembly', 'Circumferential Driller', 'Friction Stir Welding'] | AJ3: ['Automation', 'Factory integration', 'Tooling services', 'Design', 'Manufacturing', 'Installation of automated tooling and equipment', 'Assembly of aerospace structures', 'Wire EDM', 'CNC machining services', 'Resistance welding and reflow soldering tool division', 'Precision machining', 'Product finishing (polishing, plating, anodizing, assembly, packaging)', 'AI/IoT solutions', 'Data visualization/mining', 'Predictive analytics', 'Cloud infrastructure', 'Operations/monitoring services', 'Hardware and software sales (centered on IBM products)', 'Infrastructure development', 'Technical support', 'IT infrastructure services', 'Open technology utilization services'] | AK3: ['Nova-Tech Engineering', 'KUKA Systems Aerospace North America'] | AL3: 2805 E. Plano Pkwy, Suite 300, Plano, TX 75074 USA | AM3: ['Plano, Texas', 'Chesterfield Twp, Michigan', 'Bothell, Washington', 'Leganés, Spain', 'Umeå, Sweden', 'France', 'Germany', 'San Antonio, Texas', 'Grand Prairie, Texas', 'Canada'] | AN3: ait@aint.com | AO3: https://www.aint.com/contact_ait/overview | AP3: https://www.linkedin.com/company/ims-ab-innovative-mobility-system-, https://www.youtube.com/, https://twitter.com/ | AQ3: 19 | AR3: 15+ | AS3: 5 | AT3: 9 | AU3: 10081.0|10345.0|10631.0|11760.0|12317.0|12535.0|12541.0|14157.0|1550.0|15515.0|15604.0|15731.0|16427.0|16509.0|17077.0|17079.0|17091.0|17146.0|17148.0|17284.0|17342.0|17343.0|17392.0|17611.0|17648.0|17693.0|18361.0|18746.0|18855.0|18939.0|19159.0|19248.0|19643.0|20204.0|20288.0|21762.0|22028.0|22125.0|22292.0|22614.0|22711.0|22907.0|25872.0|25874.0|26236.0|2645.0|26573.0|2827.0|2862.0|29239.0|2967.0|30901.0|3170.0|31941.0|32408.0|32487.0|32608.0|32662.0|34046.0|34793.0|35217.0|35245.0|35499.0|35553.0|35597.0|35646.0|35996.0|36044.0|36077.0|36350.0|36486.0|36651.0|36685.0|36715.0|36813.0|36938.0|37287.0|37547.0|40206.0|40793.0|40840.0|40951.0|410.0|41477.0|41573.0|4198.0|42334.0|42478.0|42500.0|42552.0|43426.0|445.0|4684.0|5489.0|5639.0|6066.0|6399.0|7175.0|7330.0|7477.0|7512.0|760.0|779.0|8267.0|8481.0|8617.0|8879.0|9290.0|9595.0|9667.0|9719.0|9816.0|9968.0 | AV3: Collaborate Design & Publish|Customer Service|Data Management Business Intelligence & Analytics|Emerging Technology|Enterprise Business Solution|Financial Management & GRC|Hardware|Human Capital Management|IT Development/Infrastructure|Marketing|Network Security Monitoring|Operations|Sales|Security Devices|Servers|Storage|Supply Chain Management|Verticals | AW3: Academic & Education Management|Accounting/Finance/Treasury|Application Development Tools|Artificial Intelligence & Machine Learning|Business Intelligence|CAD/CAM|CRM|Construction|Data Security & Data Loss Prevention DLP|Database Management|Design & Publishing Software|Document Management|Domain Name Services|Email Software|Endpoint Security|Enterprise Resource Planning|Event Management|Firewall Software|Frameworks & Libraries|Human Resources Management|IT Infrastructure & Ops Management|IT Service Management ITSM|Identity & Access Management IAM|Network Attached Storage|Network Hardware|Network Management Software|Operating System|Other Collaboration Software|Other Emerging Technology|Other Hardware|Other IT Development/Infrastructure|Other Operations Software|Other Security Software|Other Vertical Industries Software|Personal Computer|Personalized Marketing|Programming Languages|Project Management Software|Router|Server|Server Virtualization|Suites|Supply Chain Management|Unified Communications Services|Web Analytics|Web Hosting | AX3: 3D Modeling Software|3D Scanning and Measurement|3D Virtualization|Antivirus Solutions|Authentication Platforms|Automotive Dealership Management|Background Screening|Backup and Recovery Solutions|Billing and Subscription Management|CNC Programming Software|Cloud DNS Services|Cloud Hosting|Cloud Networking|Cloud Platforms|Customer Experience Optimization|Data Visualization|Database Languages|Design Collaboration Tools|Desktop Operating Systems|Directory Services|Document Publishing Tools|Document Workflow Automation|Domain Registrars|Email Hosting|Encryption & Key Management|Enterprise Analytics Platforms|Enterprise Resource Planning (ERP)|Environmental Health and Safety Management|Event Scheduling Tools|Event Tracking Tools|Firewall Management Tools|Frontend Frameworks|General CAD Software|General ERP|General-Purpose Languages|Global Payroll|Hardware Communication Solutions|Human Capital Management|Identity Verification|Industrial Automation|Industrial Automation CAD|Industrial Automation Software|Industrial Automation Solutions|Knowledge Management|Linux Distributions|Low-Level Languages|Machine Vision Systems|Manufacturing ERP|Measurement and Analysis Software|Mechanical CAD|Mobile Frameworks|Mobile Web Tools|Network Analysis|Network Firewalls|Network Security Appliances|Operating Systems|Presentation Tools|Privacy and Security Tools|Productivity Suites|Project Management Platforms|Recruitment Platforms|Relational Databases|Routers|Server Operating Systems|Service Desk Software|Shared Hosting|Small Business CRM|Specialized Training Tools|Spreadsheet Collaboration Tools|Switches|Task and Workflow Management|Telephony and VoIP Systems|Testing Tools|Transportation and Logistics|Travel Management|UI Frameworks|Unclassified|VPN Appliances|Web Development|Web Servers|Wireless Network Hardware | AY3: AD360|AWS Amazon Web Services|Adobe FrameMaker|Amazon Web Hosting|Apache Servers|Apple|Apple Mobile Web Clips Icon|Aria|Assemble|Assembly|Autodesk|Autodesk AutoCAD|Azure DNS|C|C++|CATIA|CATIA V5|CSS|Ceridian|Cisco Adaptive Security Appliance ASA|Cisco Firepower|Cisco Firepower Management Center|Cisco Meraki|Cisco Routers|Cisco Switches|Cisco VPN|Cisco Wireless|Cisco common|Clearance Jobs|Cognex|Computer Aid|Craft|DIS|Dassault Systemes|Dayforce HCM|Debian|Dell Technologies|EBI|Entrust|FactoryTalk|FactoryTalk View|Faro Technologies|FedEx|Firewalls|GoDaddy DNS|Google Analytics|Google Global Site Tag|Google Universal Analytics|Guru|Hammerjs|IFS|IFS Applications|IFS ERP|IFS Enterprise Resource Planning|Insider|Inteliquent|JavaScript|Lean Manufacturing|Linux|ManageEngine ServiceDesk Plus|Mastercam|Microsoft|Microsoft Excel|Microsoft Exchange Online|Microsoft Office 365|Microsoft PowerPoint|Microsoft Project|Microsoft SQL Server|Microsoft common|NTENT Hosting|Open Graph Protocol|Oracle|Oracle PL/SQL|PHP|PTC Creo|Persona|Polycom|Power BI|Prove formerly Payfone|Quali|Relay|Remote|RequireJS|Resolve|Riverbed Wireshark|SAP|SQL|Scala|Sched|Siemens|Siemens SIMATIC S7|Solidworks|Sophos|SpatialAnalyzer|StorageCraft ShadowProtect|Studio 5000|SugarCRM|Tebis|Tor|VIA|VMware common|Verisurf|Windows 10|Windows Server|X-UA-Compatible|cyber security|fancyBox|iOS|jQuery|jQuery Migrate|jQuery Mobile|ventiv | AZ3: AWS|Adobe Systems Inc.|Amazon|Apache Software Foundation|Apple|Aria Systems|Autodesk|CNC Software|COMPILER|Ceridian Corporation|Cisco|Cognex Corporation|Computer Aid Inc|Craft.io Ltd.|DHI Group Inc|Dassault Systemes|Dealer Information Systems Corporation|Dell|EPFL|Eight Media|Employment Background Investigations Inc|Entrust Corporation|FARO Technologies Inc.|Facebook|FedEx Corporation|Gemba Academy LLC|GoDaddy|Google|Guru Technologies Inc.|IFS|INSIDER.|Inteliquent|International Organization for Standardization|Microsoft|NTENT|Netscape|New River Kinematics|Open Source|Oracle|PTC|Persona Identities Inc|Polycom|Primenet Limited|Prove|QualiSystems Ltd|Remote Technology Inc|RequireJS|Resolve Systems|Riverbed Technology|Rockwell Automation|SAP|SCHED LLC|SOFTWARE IN THE PUBLIC INTEREST INC|Siemens|Sophos|Standard C++ Foundation|StorageCraft|Sugar CRM Inc|Tebis|The jQuery Foundation Inc|Tor Project Inc|Unspecified|VIA Institute on Character|VMware|Ventiv Technology Australia PTY Ltd|Verisurf|World Wide Web Consortium|Zoho|fancyapps | BA3: 17 | BB3: 34 | BC3: 52 | BD3: 112 | BE3: 46 | BF3: 0.30065359 | BG3: 0 | BH3: 0 | BI3: 1 | BJ3: 1 | BK3: 1 | BL3: Advanced | BM3: High | BN3: 0.38058252 | BO3: 0.845 | BP3: 1 | BQ3: 5 | BR3: 0 | BS3: 0 | BT3: 1 | BU3: 2 | BV3: 0 | BW3: 0 | BX3: 1 | BY3: 10 | BZ3: 1 | CA3: 13 | CB3: 1 | CC3: 6 | CD3: 1 | CE3: 3 | CF3: 1 | CG3: 1 | CH3: 1 | CI3: 1 | CJ3: 0 | CK3: 0 | CL3: 0 | CM3: 0 | CN3: 0 | CO3: 0 | CP3: 0 | CQ3: 0 | CR3: 1 | CS3: 2 | CT3: 0 | CU3: 0 | CV3: 1 | CW3: 61 | CX3: 0 | CY3: 0 | CZ3: 0 | DA3: 0 | DB3: 0 | DC3: 0 | DD3: 13448104 | DE3: 13.3M – 57.2M | DF3: 1169687 | DG3: 700K – 2.7M | DH3: 4271278 | DI3: 2.4M – 7.7M | DJ3: 1048132 | DK3: 500K – 1.3M | DL3: 3655322 | DM3: 800K – 3.9M | DN3: 1291360 | DO3: 400K – 2.4M | DP3: 2012325 | DQ3: 2.0M – 8.9M | DR3: High | DS3: 60477.01 | DT3: 0 | DU3: 0 | DV3: 0 | DW3: 0 | DX3: 76 | DY3: 2923 | DZ3: 377 | EA3: 0.019349088 | EB3: 0.0018817068 | EC3: 0 | ED3: 0.001610116 | EE3: 0.18328246 | EF3: 0.00069592561 | EG3: 0.00032781052 | EH3: 0 | EI3: 0.0048586645 | EJ3: 0.0007713675 | EK3: 0.00042247459 | EL3: 7.440844e-06 | EM3: 1 | EN3: SECURITY_NETWORK | EO3: 0.18328246 | EP3: 0 | EQ3: 0 | ER3: 0 | ES3: 1 | EU3: 377 | GU3: 0.47 | GV3: Medium | GW3: 46042.637 | GX3: 46069.558 | GZ3: 3-5 | HA3: 6-10 | HB3: "{\"lead_label\": \"Medium\", \"lead_score\": 0.47, \"tech_reasoning\": \"Tech relevancy unknown.\", \"competitive_reasoning\": \"No competitor or primary vendor usage detected\", \"key_signals\": \"Firmographics: revenue range redefined buckets: $10M - $100M; employee range redefined buckets: 150 - 300; naics industry: Manufacturing; location type: Sub-Urban; years in business buckets: 15+; total sites local buckets: 3-5; total sites global buckets: 6-10 | Spend: spend priority label llm: High\"}"
A4: d4ac5c2b-46cd-5bdb-8107-27159032ad26 | B4: =VLOOKUP(C4,Complete!#REF!,1,0) -> #REF! | C4: Aerospace Manufacturing Corporation | D4: https://www.aero-space.us/ | E4: 94A3272655954373 | F4: Aerospace Manufacturing Corporation | G4: Aerospace Manufacturing Corporation | H4: 80 Van Winkle Ave | I4: Wallington | J4: New Jersey | K4: United States | L4: Sub-Urban | M4: 07057 | N4: North America | O4: aero-space.us | P4: +1 973 472 2300 | U4: 1986 | V4: 208 | W4: 150 - 300 | X4: $10M - $100M | Y4: Aerospace and Aircraft Manufacturing | Z4: Manufacturing | AA4: 45 | 3721 | 3724 | 3728 | 3764 | 3769 | 9661 | 769922 | AB4: 45 - Transportation By Air | 3721 - Aircraft | 3724 - Aircraft Engines And Engine Parts | 3728 - Aircraft Parts And Equipment, Nec | 3764 - Space Propulsion Units And Parts | 3769 - Space Vehicle Equipment, Nec | 9661 - Space Research And Technology | 769922 - Aircraft And Heavy Equipment Repair Services | AC4: 481 | 3336 | 3364 | 48811 | AD4: 481 - Air Transportation | 3336 - Engine, Turbine, and Power Transmission Equipment Manufacturing | 3364 - Aerospace Product and Parts Manufacturing | 48811 - Airport Operations | AE4: No | AF4: Privately Held | AG4: Aerospace fastener manufacturer | AH4: Aerospace Manufacturing (AMI) produces a diversified product line of high strength, close tolerance aerospace fasteners for world-class OEM leaders. The company also offers custom manufacturing processes for both standard and custom fasteners. | AI4: ['MS21250 Aerospace Bolts', 'MS14181 Aerospace Bolts', 'MS21296 Fasteners', 'Phillips-Licensed Products', 'Standard Fasteners', 'Metric Fasteners', 'Blanks Program', 'Screws', 'Bolts', 'Pins', 'Studs', 'Threaded Rods'] | AJ4: ['Custom Manufacturing'] | AL4: P.O. Box 3398, 80 Van Winkle Ave. Wallington, NJ 07057 | AM4: ['Wallington, NJ'] | AN4: AEROSPACE@AERO-SPACE.US | AO4: https://www.aero-space.us/contact/ | AP4: https://www.linkedin.com/company/aerospace-manufacturing-corporation, https://twitter.com/aerospace_manuf, https://www.facebook.com/aerospacemanufacturingcorp/ | AQ4: 40 | AR4: 15+ | AS4: 1 | AT4: 1 | AU4: 10613.0|10638.0|10641.0|11215.0|15604.0|15731.0|16255.0|16260.0|16361.0|16498.0|16509.0|16538.0|16684.0|17883.0|18361.0|18746.0|22907.0|24897.0|28750.0|35553.0|35717.0|36499.0|36715.0|40667.0|410.0|5159.0|5489.0|646.0|6558.0|7523.0|8520.0|8754.0|8810.0|8821.0|8834.0|9688.0 | AV4: Collaborate Design & Publish|Data Management Business Intelligence & Analytics|Hardware|IT Development/Infrastructure|Marketing|Network Security Monitoring|Other|Verticals|Web Tools & Plugins | AW4: Application Server Software|Business Intelligence|CAPTCHA|Content Delivery Networks|Database Management|Domain Name Services|Email Software|Frameworks & Libraries|IT Infrastructure & Ops Management|Marketing Automation|Marketing Performance Management|Multimedia|Network Management Software|Other|Other Marketing Software|Other Vertical Industries Software|Other Web Tools & Plugins|Programming Languages|Search Marketing|Software as a Service|Suites|Web Analytics|Web Content Management Systems|Web Hosting | AX4: Business Data Services|Cloud CDN Providers|Domain Registrars|E-commerce Analytics|Email Hosting|Email Marketing Platforms|Enterprise Analytics Platforms|Environmental Health and Safety Management|Event Tracking Tools|Form Builders|Frontend Frameworks|General CAPTCHA Solutions|Google CAPTCHA Solutions|Icon Libraries|Managed Hosting|Open Source CMS|Open Source and Free CDN Providers|Productivity Suites|SEO Tools|Session Replay Tools|Social Media Marketing Tools|Stock Media Platforms|Tag Management Systems|Testing Tools|UI Frameworks|Unclassified|Web Development|Web Development Frameworks|Web Performance and Security|Web Server Management|Website Optimization Tools | AY4: AMI|ASP.NET|CAPTCHA common|CSS|CloudFlare|Cloudflare CDN|Cloudflare Website Optimization|Dun & Bradstreet|Font Awesome|Gmail for business|Google Analytics|Google Global Site Tag|Google Hosted Libraries|Google Tag Manager|Google Universal Analytics|Google Workspace formerly G Suite|Gravity Forms|Inspectlet|Modernizr|Network Solutions DNS|PHP|Quali|SharpSpring|Shutterstock|ThomasNet Web Traxs|Twitter Cards|WP Engine|WordPress.org|Yoast|Yoast SEO|fancyBox|jQuery|jQuery Migrate|nginx|reCAPTCHA|ventiv | AZ4: BMC Software|COMPILER|CloudFlare|Dun & Bradstreet Inc.|Fonticons Inc.|Google|Inspectlet|Microsoft|Modernizr|Network Solutions|Open Source|Pennant Group Inc.|QualiSystems Ltd|Sharpspring Inc.|Shutterstock Inc.|The jQuery Foundation Inc|Twitter Inc.|Unspecified|Ventiv Technology Australia PTY Ltd|WPEngine Inc.|WordPress|World Wide Web Consortium|Yoast B.V|fancyapps | BA4: 1 | BB4: 11 | BC4: 21 | BD4: 36 | BE4: 24 | BF4: 0.15686275 | BG4: 0 | BH4: 0 | BI4: 1 | BJ4: 1 | BK4: 1 | BL4: Advanced | BM4: Medium | BN4: 0.26060606 | BO4: 0.815 | BP4: 1 | BQ4: 1 | BR4: 0 | BS4: 0 | BT4: 1 | BU4: 1 | BV4: 0 | BW4: 0 | BX4: 1 | BY4: 8 | BZ4: 1 | CA4: 2 | CB4: 0 | CC4: 0 | CD4: 0 | CE4: 0 | CF4: 0 | CG4: 0 | CH4: 0 | CI4: 0 | CJ4: 0 | CK4: 0 | CL4: 0 | CM4: 0 | CN4: 0 | CO4: 0 | CP4: 0 | CQ4: 0 | CR4: 1 | CS4: 5 | CT4: 0 | CU4: 0 | CV4: 1 | CW4: 19 | CX4: 0 | CY4: 0 | CZ4: 0 | DA4: 0 | DB4: 0 | DC4: 0 | DD4: 13023101 | DE4: 2.6M – 13.3M | DF4: 648050 | DG4: 100K – 700K | DH4: 1393344 | DI4: 500K – 2.4M | DJ4: 329410 | DK4: 100K – 500K | DL4: 5611444 | DM4: 3.9M – 18.0M | DN4: 3001844 | DO4: 2.4M – 7.6M | DP4: 2039009 | DQ4: 2.0M – 8.9M | DR4: Very High | DS4: 289.4 | DT4: 0 | DU4: 0 | DV4: 0 | DW4: 0 | DX4: 0 | DY4: 0 | DZ4: 8 | EA4: 0 | EB4: 0 | EC4: 0 | ED4: 0 | EE4: 0.11273324 | EF4: 0 | EG4: 0 | EH4: 0 | EI4: 0 | EJ4: 0 | EK4: 0 | EL4: 0 | EM4: 1 | EN4: SECURITY_NETWORK | EO4: 0.11273324 | EP4: 0 | EQ4: 0 | ER4: 0 | ES4: 0 | ET4: HIGH | EU4: 8 | GU4: 0.58 | GV4: Medium | GW4: 46042.637 | GX4: 46069.558 | GZ4: 1-2 | HA4: 1-5 | HB4: "{\"lead_label\": \"Medium\", \"lead_score\": 0.58, \"tech_reasoning\": \"Tech relevancy unknown.\", \"competitive_reasoning\": \"No competitor or primary vendor usage detected\", \"key_signals\": \"Firmographics: revenue range redefined buckets: $10M - $100M; employee range redefined buckets: 150 - 300; naics industry: Manufacturing; location type: Sub-Urban; years in business buckets: 15+; total sites local buckets: 1-2; total sites global buckets: 1-5 | Intent: intent quality tier: HIGH | Spend: spend priority label llm: Very High\"}"
